<?xml version="1.0"?>
<robot xmlns:xacro="http://www.ros.org/wiki/xacro" name="LRMate">

    <xacro:arg name="ns_header" default="fanuc"/>
    <xacro:arg name="base_position_x" default="0.0"/>
    <xacro:arg name="base_position_y" default="0.0"/>
    <xacro:arg name="base_position_z" default="0.0"/>
    <xacro:arg name="base_euler_r" default="0.0"/>
    <xacro:arg name="base_euler_p" default="0.0"/>
    <xacro:arg name="base_euler_y" default="0.0"/>

	<xacro:property name="ns_header" value="$(arg ns_header)"/>
	<xacro:property name="base_position_x" value="$(arg base_position_x)"/>
	<xacro:property name="base_position_y" value="$(arg base_position_y)"/>
	<xacro:property name="base_position_z" value="$(arg base_position_z)"/>
	<xacro:property name="base_euler_r" default="$(arg base_euler_r)"/>
	<xacro:property name="base_euler_p" default="$(arg base_euler_p)"/>
	<xacro:property name="base_euler_y" default="$(arg base_euler_y)"/>

	<material name="${ns_header}_Yellow">
		<color rgba="1.0  1.0  0.0  1.0"/>
	</material>
	<material name="${ns_header}_Black">
		<color rgba="0.0  0.0  0.0  1.0"/>
	</material>
	<material name="${ns_header}_Gray">
		<color rgba="0.5  0.5  0.5  1.0"/>
	</material>
	<material name="${ns_header}_Gray_2">
		<color rgba="1.0  1.0  1.0  1.0"/>
	</material>

    <link name="world">
    </link>

    <joint name="world_to_${ns_header}" type="fixed">
        <origin rpy="${base_euler_r} ${base_euler_p} ${base_euler_y}" xyz="$(arg base_position_x) $(arg base_position_y) $(arg base_position_z)"/>
        <parent link="world"/>
        <child link="${ns_header}_base"/>
    </joint>

	<link name="${ns_header}_base">
		<inertial>
			<origin xyz="0.0  0.0  0.0" rpy="0.0  0.0  0.0"/>
			<mass value="0.0"/>
			<inertia ixx="0.0"  ixy="0.0"  ixz="0.0" iyy="0.0" iyz="0.0" izz="0.0" />
		</inertial>
		<visual name="${ns_header}_base">
			<origin xyz="0.000   0.000   0.330" rpy="0.0  0.0  0.0"/>
			<geometry>
				<mesh filename="package://fanuc_description/urdf/lrmate/CAD/base.stl" scale="0.001   0.001   0.001"/>
			</geometry>
			<material name="${ns_header}_Gray"/>
		</visual>
		<collision>
			<origin xyz="0.000   0.000   0.330" rpy="0.0  0.0  0.0"/>
			<geometry>
				<mesh filename="package://fanuc_description/urdf/lrmate/CAD/base.stl" scale="0.001   0.001   0.001"/>
			</geometry>
		</collision>
	</link>
	<joint name="${ns_header}_joint_1" type="revolute">
		<origin xyz="0.000   0.000   0.330" rpy="0.0000000000000000    0.0000000000000000    0.0000000000000000"/>
		<parent link="${ns_header}_base"/>
		<child link="${ns_header}_link_1"/>
		<axis xyz="0 0 1"/>
		<limit effort="224.1470270270270646" lower="-3.1415926535897931" upper="3.1415926535897931" velocity="0.8726646259971648"/>
	</joint>
	<link name="${ns_header}_link_1">
		<inertial>
			<origin xyz="0.0185909590000000    0.0033700950000000   -0.0770907100000000" rpy="-1.5707963267948966    0.0000000000000000    0.0000000000000000"/>
			<mass value="2.3984700000000001"/>
			<inertia ixx="0.0233179728630000"  ixy="0.0000000000000000"  ixz="0.0000000000000000" iyy="0.0193776178710000" iyz="0.0000000000000000" izz="0.0139141526340000" />
		</inertial>
		<visual name="${ns_header}_link_1">
			<origin xyz="0.050   0.000   0.000" rpy="-1.5707963267948966    0.0000000000000000    0.0000000000000000"/>
			<geometry>
				<mesh filename="package://fanuc_description/urdf/lrmate/CAD/link1.stl" scale="0.001   0.001   0.001"/>
			</geometry>
			<material name="${ns_header}_Yellow"/>
		</visual>
		<collision>
			<origin xyz="0.050   0.000   0.000" rpy="-1.5707963267948966    0.0000000000000000    0.0000000000000000"/>
			<geometry>
				<mesh filename="package://fanuc_description/urdf/lrmate/CAD/link1.stl" scale="0.001   0.001   0.001"/>
			</geometry>
		</collision>
	</link>
	<joint name="${ns_header}_joint_2" type="revolute">
		<origin xyz="0.050   0.000   0.000" rpy="-1.5707963267948966    0.0000000000000000    0.0000000000000000"/>
		<parent link="${ns_header}_link_1"/>
		<child link="${ns_header}_link_2"/>
		<axis xyz="0 0 1"/>
		<limit effort="236.6760000000000161" lower="-3.1415926535897931" upper="3.1415926535897931" velocity="0.8726646259971648"/>
	</joint>
	<link name="${ns_header}_link_2">
		<inertial>
			<origin xyz="-0.0071079890000000   -0.1326139250000000    0.0247800790000000" rpy="3.1415926535897931    0.0000000000000000   -1.5707963267948966"/>
			<mass value="7.8018689999999999"/>
			<inertia ixx="0.0328971739050000"  ixy="0.0000000000000000"  ixz="0.0000000000000000" iyy="0.2070365793270000" iyz="0.0000000000000000" izz="0.1883991938960000" />
		</inertial>
		<visual name="${ns_header}_link_2">
			<origin xyz="0.000  -0.440   0.000" rpy="3.1415926535897931    0.0000000000000000   -1.5707963267948966"/>
			<geometry>
				<mesh filename="package://fanuc_description/urdf/lrmate/CAD/link2.stl" scale="0.001   0.001   0.001"/>
			</geometry>
			<material name="${ns_header}_Yellow"/>
		</visual>
		<collision>
			<origin xyz="0.000  -0.440   0.000" rpy="3.1415926535897931    0.0000000000000000   -1.5707963267948966"/>
			<geometry>
				<mesh filename="package://fanuc_description/urdf/lrmate/CAD/link2.stl" scale="0.001   0.001   0.001"/>
			</geometry>
		</collision>
	</link>
	<joint name="${ns_header}_joint_3" type="revolute">
		<origin xyz="0.000  -0.440   0.000" rpy="3.1415926535897931    0.0000000000000000   -1.5707963267948966"/>
		<parent link="${ns_header}_link_2"/>
		<child link="${ns_header}_link_3"/>
		<axis xyz="0 0 1"/>
		<limit effort="94.9241379310344939" lower="-3.1415926535897931" upper="3.1415926535897931" velocity="0.8726646259971648"/>
	</joint>
	<link name="${ns_header}_link_3">
		<inertial>
			<origin xyz="0.0057931330000000   -0.0059066300000000   -0.0207324280000000" rpy="-1.5707963267948966    0.0000000000000000    0.0000000000000000"/>
			<mass value="2.9847210000000000"/>
			<inertia ixx="0.0081019474240000"  ixy="0.0000000000000000"  ixz="0.0000000000000000" iyy="0.0068697082660000" iyz="0.0000000000000000" izz="0.0079818513480000" />
		</inertial>
		<visual name="${ns_header}_link_3">
			<origin xyz="0.035   0.000   0.000" rpy="-1.5707963267948966    0.0000000000000000    0.0000000000000000"/>
			<geometry>
				<mesh filename="package://fanuc_description/urdf/lrmate/CAD/link3.stl" scale="0.001   0.001   0.001"/>
			</geometry>
			<material name="${ns_header}_Yellow"/>
		</visual>
		<collision>
			<origin xyz="0.035   0.000   0.000" rpy="-1.5707963267948966    0.0000000000000000    0.0000000000000000"/>
			<geometry>
				<mesh filename="package://fanuc_description/urdf/lrmate/CAD/link3.stl" scale="0.001   0.001   0.001"/>
			</geometry>
		</collision>
	</link>
	<joint name="${ns_header}_joint_4" type="revolute">
		<origin xyz="0.035   0.000   0.000" rpy="-1.5707963267948966    0.0000000000000000    0.0000000000000000"/>
		<parent link="${ns_header}_link_3"/>
		<child link="${ns_header}_link_4"/>
		<axis xyz="0 0 1"/>
		<limit effort="23.8998260869565229" lower="-3.1415926535897931" upper="3.1415926535897931" velocity="0.8726646259971648"/>
	</joint>
	<link name="${ns_header}_link_4">
		<inertial>
			<origin xyz="-0.0002457140000000    0.0028224150000000   -0.2060611280000000" rpy="1.5707963267948966    0.0000000000000000    0.0000000000000000"/>
			<mass value="4.1441780000000001"/>
			<inertia ixx="0.0529101059260000"  ixy="0.0000000000000000"  ixz="0.0000000000000000" iyy="0.0057046189630000" iyz="0.0000000000000000" izz="0.0531509714450000" />
		</inertial>
		<visual name="${ns_header}_link_4">
			<origin xyz="0.000   0.000  -0.420" rpy="1.5707963267948966    0.0000000000000000    0.0000000000000000"/>
			<geometry>
				<mesh filename="package://fanuc_description/urdf/lrmate/CAD/link4.stl" scale="0.001   0.001   0.001"/>
			</geometry>
			<material name="${ns_header}_Yellow"/>
		</visual>
		<collision>
			<origin xyz="0.000   0.000  -0.420" rpy="1.5707963267948966    0.0000000000000000    0.0000000000000000"/>
			<geometry>
				<mesh filename="package://fanuc_description/urdf/lrmate/CAD/link4.stl" scale="0.001   0.001   0.001"/>
			</geometry>
		</collision>
	</link>
	<joint name="${ns_header}_joint_5" type="revolute">
		<origin xyz="0.000   0.000  -0.420" rpy="1.5707963267948966    0.0000000000000000    0.0000000000000000"/>
		<parent link="${ns_header}_link_4"/>
		<child link="${ns_header}_link_5"/>
		<axis xyz="0 0 1"/>
		<limit effort="13.8166666666666664" lower="-3.1415926535897931" upper="3.1415926535897931" velocity="0.8726646259971648"/>
	</joint>
	<link name="${ns_header}_link_5">
		<inertial>
			<origin xyz="0.0000480440000000   -0.0273839680000000   -0.0044381510000000" rpy="-1.5707963267948966    0.0000000000000000    0.0000000000000000"/>
			<mass value="1.8704200000000000"/>
			<inertia ixx="0.0024795564500000"  ixy="0.0000000000000000"  ixz="0.0000000000000000" iyy="0.0024375453070000" iyz="0.0000000000000000" izz="0.0012003431970000" />
		</inertial>
		<visual name="${ns_header}_link_5">
			<origin xyz="0.000   0.000   0.000" rpy="-1.5707963267948966    0.0000000000000000    0.0000000000000000"/>
			<geometry>
				<mesh filename="package://fanuc_description/urdf/lrmate/CAD/link5.stl" scale="0.001   0.001   0.001"/>
			</geometry>
			<material name="${ns_header}_Yellow"/>
		</visual>
		<collision>
			<origin xyz="0.000   0.000   0.000" rpy="-1.5707963267948966    0.0000000000000000    0.0000000000000000"/>
			<geometry>
				<mesh filename="package://fanuc_description/urdf/lrmate/CAD/link5.stl" scale="0.001   0.001   0.001"/>
			</geometry>
		</collision>
	</link>

	<!-- gripper -->
	<link name="${ns_header}_gripper_hand">
		<inertial>
			<origin rpy="0 0 0" xyz="0 0 0.04"/>
			<mass value=".81"/>
			<inertia ixx="0.1" ixy="0" ixz="0" iyy="0.1" iyz="0" izz="0.1"/>
		</inertial>
		<visual>
			<geometry>
				<mesh filename="package://fanuc_description/urdf/lrmate/CAD/gripper_2/visual/sensor_hand.stl" scale="0.001 0.001 0.001"/>
			</geometry>
			<material name="${ns_header}_Gray_2"/>
		</visual>
		<collision>
		<geometry>
			<mesh filename="package://fanuc_description/urdf/lrmate/CAD/gripper_2/collision/sensor_hand.stl" scale="0.001 0.001 0.001"/>
		</geometry>
		<material name="${ns_header}_Gray_2"/>
		</collision>
  	</link>

  	<link name="${ns_header}_gripper_leftfinger">
		<contact>
			<friction_anchor/>
			<stiffness value="30000.0"/>
			<damping value="1000.0"/>
			<spinning_friction value="0.1"/>
			<!-- <rolling_friction value="0.1"/> -->
			<lateral_friction value="1.0"/>
		</contact>
		<inertial>
			<origin rpy="0 0 0" xyz="0 0.01 0.02"/>
			<mass value="0.1"/>
			<inertia ixx="0.1" ixy="0" ixz="0" iyy="0.1" iyz="0" izz="0.1"/>
		</inertial>
		<visual>
			<geometry>
				<mesh filename="package://fanuc_description/urdf/lrmate/CAD/gripper_2/visual/finger.stl" scale="0.001 0.001 0.001"/>
			</geometry>
			<material name="${ns_header}_Gray_2"/>
		</visual>
		<collision>
			<geometry>
				<mesh filename="package://fanuc_description/urdf/lrmate/CAD/gripper_2/collision/finger.stl" scale="0.001 0.001 0.001"/>
			</geometry>
			<material name="${ns_header}_Gray_2"/>
		</collision>
	</link>

  	<link name="${ns_header}_gripper_rightfinger">
    	<contact>
			<friction_anchor/>
			<stiffness value="30000.0"/>
			<damping value="1000.0"/>
			<spinning_friction value="0.1"/>
			<!-- <rolling_friction value="0.1"/> -->
			<lateral_friction value="1.0"/>
		</contact>

  		<inertial>
			<origin rpy="0 0 0" xyz="0 -0.01 0.02"/>
			<mass value="0.1"/>
			<inertia ixx="0.1" ixy="0" ixz="0" iyy="0.1" iyz="0" izz="0.1"/>
		</inertial>
		<visual>
			<origin rpy="0 0 3.14159265359" xyz="0 0 0"/>
			<geometry>
				<mesh filename="package://fanuc_description/urdf/lrmate/CAD/gripper_2/visual/finger.stl" scale="0.001 0.001 0.001"/>
			</geometry>
			<material name="${ns_header}_Gray_2"/>
		</visual>
		<collision>
			<origin rpy="0 0 3.14159265359" xyz="0 0 0"/>
			<geometry>
				<mesh filename="package://fanuc_description/urdf/lrmate/CAD/gripper_2/collision/finger.stl" scale="0.001 0.001 0.001"/>
			</geometry>
			<material name="${ns_header}_Gray_2"/>
		</collision>
  	</link>

	<joint name="${ns_header}_joint_6" type="revolute">
        <origin rpy="0.0 1.5707963267948966 0.0" xyz="0 -0.0775 0.0"/>
        <parent link="${ns_header}_link_5"/>
        <child link="${ns_header}_gripper_hand"/>
		<axis xyz="0 1 0"/>
		<limit effort="6.8606896551724139" lower="-3.1415926535897931" upper="3.1415926535897931" velocity="0.8726646259971648"/>
    </joint>

	<joint name="${ns_header}_finger_joint1" type="prismatic">
		<parent link="${ns_header}_gripper_hand"/>
		<child link="${ns_header}_gripper_leftfinger"/>
		<origin rpy="0 -1.5707963267948966 0" xyz="-0.04 -0.150 0"/>
		<axis xyz="0 0 -1"/>
		<limit effort="1000" lower="0.0" upper="0.04" velocity="2.0"/>
	</joint>


	<joint name="${ns_header}_finger_joint2" type="prismatic">
		<parent link="${ns_header}_gripper_hand"/>
		<child link="${ns_header}_gripper_rightfinger"/>
		<origin rpy="3.14159265359 -1.5707963267948966 0" xyz="0.04 -0.150 0"/>
		<axis xyz="0 0 -1"/>
		<limit effort="1000" lower="0.0" upper="0.04" velocity="2.0"/>
		<mimic joint="${ns_header}_finger_joint1"/>
	</joint>

	<!-- grasp target -->
	<link name="${ns_header}_grasptarget">
     	<inertial>
      		<origin rpy="0 0 0" xyz="0 0 0"/>
       		<mass value="0.001"/>
       		<inertia ixx="0.1" ixy="0" ixz="0" iyy="0.1" iyz="0" izz="0.1"/>
    	</inertial>
    	<visual>
      		<geometry>
        		<sphere radius="0.003"/>
      		</geometry>
      		<color rgba="1. 0. 0. 1.0"/>
    	</visual>
   </link>

	<joint name="${ns_header}_lrmate_grasptarget_hand" type="fixed">
		<parent link="${ns_header}_gripper_hand"/>
		<child link="${ns_header}_grasptarget"/>
		<origin rpy="1.5707963267948966 -1.5707963267948966 0" xyz="0 -0.245 0"/>
	</joint>
    
</robot>
